Workbook

Sheet How_To_Use
A1: AM Calendar — ไฮดรอลิก + ระบบลม (自主保全カレンダー = ปฏิทิน AM รวม)
A2: รวมกิจกรรม CILT จาก AM_Standard_Hydraulic_Unit.xlsx และ AM_Standard_Pneumatic_System.xlsx ลงปฏิทินเดียว สำหรับเครื่องที่มีทั้ง 2 ระบบ
A4: ชีท | B4: ใช้ทำอะไร
A5: AM_Calendar | B5: กิจกรรมทั้ง 2 ระบบ × 12 เดือน · No. H-xx / P-xx = ลำดับในชีท AM_Standard ของแต่ละระบบ · เลื่อนเดือนของงานตามรอบได้ (แก้ตัวอักษรในช่องเดือน)
A6: Monthly_Load | B6: เวลา AM ต่อเดือน (นาที) แยกระบบและงาน PM · ใช้สูตรอ่านจาก AM_Calendar · ช่องเหลือง = วันทำงาน/สัปดาห์ต่อเดือน
A7: Periodic_Record | B7: แผน vs ผลจริงของงานตามรอบ (3M / 6M / 1Y) · กรอกวันที่ทำ ผู้ทำ ผล · % ทำตามแผนคำนวณเอง
A8: To_Confirm | B8: ประเด็นที่ต้องยืนยันก่อนใช้จริง
A10: รหัสความถี่ | B10: D = ทุกวัน · W = รายสัปดาห์ · Q = ทุก 3 เดือน · S = ทุก 6 เดือน · A = ทุก 1 ปี · งาน “เมื่อพบ / ทุกครั้งที่ซ่อม” ไม่มีเดือน
A11: เกลี่ยภาระ (平準化) | B11: ไฮดรอลิก: Q = ทุก 3 เดือน (มี.ค. มิ.ย. ก.ย. ธ.ค. *) · S = ทุก 6 เดือน (มิ.ย. ธ.ค. *) · A = ทุก 1 ปี (ธ.ค. *) ระบบลม: Q = ทุก 3 เดือน (ม.ค. เม.ย. ก.ค. ต.ค. *) · S = ทุก 6 เดือน (มิ.ย. ธ.ค. *) · A = ทุก 1 ปี (ก.ค. *) เหตุผล: ไม่ให้งานถอดตรวจ 1 ปีของทั้ง 2 ระบบตกเดือนเดียวกัน (ข้อเสนอ * ให้วางตามแผนหยุดเครื่องจริง)
A12: บันทึกงานรายวัน/สัปดาห์ | B12: ใช้ AM_Check_Sheet ของแต่ละระบบ (คอลัมน์สุดท้ายของ AM_Calendar บอกเลขข้อ)
A13: Risk | B13: ค่าจาก FMEA ใน AM Standard ณ วันที่สร้างไฟล์ · ถ้าแก้ S/O/D ใน AM Standard ให้รันสคริปต์สร้างไฟล์นี้ใหม่
A14: ป้ายที่มา | B14: * = ข้อเสนอ · [DATA REQUIRED] = ข้อมูลของโรงงาน (ช่องเหลือง) · เวลา = ประมาณการจาก AM Standard [INFER]

Sheet AM_Calendar
A1: AM Calendar รวม — ไฮดรอลิก + ระบบลม · ปี ……
A2: D ทุกวัน · W รายสัปดาห์ · Q 3 เดือน · S 6 เดือน · A 1 ปี · เดือนของงานตามรอบเกลี่ยแล้ว (ข้อเสนอ *) · แก้ตัวอักษรในช่องเดือนได้ ชีท Monthly_Load จะคำนวณใหม่
A4: No. | B4: ระบบ | C4: Part ID | D4: กิจกรรม (Check point) | E4: CILT | F4: ความถี่ | G4: เวลา (นาที) | H4: Risk | I4: ผู้รับผิดชอบ | J4: ม.ค. | K4: ก.พ. | L4: มี.ค. | M4: เม.ย. | N4: พ.ค. | O4: มิ.ย. | P4: ก.ค. | Q4: ส.ค. | R4: ก.ย. | S4: ต.ค. | T4: พ.ย. | U4: ธ.ค. | V4: ข้อใน AM Check Sheet
A5: ระบบไฮดรอลิก
A6: ① ถังน้ำมันและน้ำมัน (Oil tank & oil)
A7: H-01 | B7: ไฮดรอลิก | C7: H01 | D7: ภายนอก Hydraulic unit · ถัง · พื้นรอบเครื่อง | E7: C | F7: D · หลังเลิกงาน | G7: 3 | H7: HIGH | I7: Operator | J7: D | K7: D | L7: D | M7: D | N7: D | O7: D | P7: D | Q7: D | R7: D | S7: D | T7: D | U7: D | V7: D11, D12, D13
A8: H-02 | B8: ไฮดรอลิก | C8: H02 | D8: ระดับน้ำมันในถัง | E8: I/L | F8: D · หลังเลิกงาน | G8: 0.5 | H8: CRITICAL | I8: Operator | J8: D | K8: D | L8: D | M8: D | N8: D | O8: D | P8: D | Q8: D | R8: D | S8: D | T8: D | U8: D | V8: D15
A9: H-03 | B9: ไฮดรอลิก | C9: H03 | D9: สีน้ำมัน (ดูที่เกจระดับ) | E9: I | F9: D · หลังเลิกงาน | G9: 0.5 | H9: CRITICAL | I9: Operator | J9: D | K9: D | L9: D | M9: D | N9: D | O9: D | P9: D | Q9: D | R9: D | S9: D | T9: D | U9: D | V9: D16
A10: H-04 | B10: ไฮดรอลิก | C10: H04 | D10: อุณหภูมิน้ำมัน | E10: I | F10: D · หลังเลิกงาน | G10: 0.5 | H10: HIGH | I10: Operator | J10: D | K10: D | L10: D | M10: D | N10: D | O10: D | P10: D | Q10: D | R10: D | S10: D | T10: D | U10: D | V10: D18
A11: H-05 | B11: ไฮดรอลิก | C11: H05 | D11: Air breather | E11: C | F11: W * | G11: 2 | H11: HIGH | I11: Operator | J11: W | K11: W | L11: W | M11: W | N11: W | O11: W | P11: W | Q11: W | R11: W | S11: W | T11: W | U11: W | V11: D17
A12: H-06 | B12: ไฮดรอลิก | C12: H06 | D12: Filter indicator (ตอนเริ่มเดิน) | E12: I | F12: D · เริ่มเดิน | G12: 0.5 | H12: CRITICAL | I12: Operator | J12: D | K12: D | L12: D | M12: D | N12: D | O12: D | P12: D | Q12: D | R12: D | S12: D | T12: D | U12: D | V12: D3
A13: H-07 | B13: ไฮดรอลิก | C13: H06 | D13: Filter: Vacuum meter / Indicator | E13: I | F13: 6M | G13: 2 | H13: CRITICAL | I13: Operator / PM * | O13: S | U13: S | V13: P1, P2
A14: ② ชุดปั๊ม (Pump unit)
A15: H-08 | B15: ไฮดรอลิก | C15: H07 | D15: เสียงปั๊มตอนเริ่มเดิน | E15: I | F15: D · เริ่มเดิน | G15: 1 | H15: CRITICAL | I15: Operator | J15: D | K15: D | L15: D | M15: D | N15: D | O15: D | P15: D | Q15: D | R15: D | S15: D | T15: D | U15: D | V15: D1, D4
A16: H-09 | B16: ไฮดรอลิก | C16: H08 | D16: เพลาปั๊ม (Shaft seal): รั่ว · ฟองอากาศในถัง | E16: I | F16: W * | G16: 1 | H16: CRITICAL | I16: Operator | J16: W | K16: W | L16: W | M16: W | N16: W | O16: W | P16: W | Q16: W | R16: W | S16: W | T16: W | U16: W | V16: D4, D12
A17: H-10 | B17: ไฮดรอลิก | C17: H10 | D17: สั่น/ร้อน ปั๊ม · มอเตอร์ | E17: I | F17: D · ขณะเดิน | G17: 1 | H17: HIGH | I17: Operator | J17: D | K17: D | L17: D | M17: D | N17: D | O17: D | P17: D | Q17: D | R17: D | S17: D | T17: D | U17: D | V17: D6
A18: H-11 | B18: ไฮดรอลิก | C18: H09 | D18: Coupling: ตั้งศูนย์ + จาระบี | E18: A/L | F18: 1Y * | G18: 20 | H18: CRITICAL | I18: PM | U18: A | V18: —
A19: H-12 | B19: ไฮดรอลิก | C19: H11 | D19: โบลต์ฝาปั๊ม (หลังงานซ่อม) | E19: T | F19: ทุกครั้งที่ซ่อม * | G19: 5 | H19: HIGH | I19: PM | V19: —
A20: ③ วาล์วควบคุม (Control valves)
A21: H-13 | B21: ไฮดรอลิก | C21: H12 | D21: Relief valve: Lock nut + แรงดันขณะทำงาน | E21: I/T | F21: D · ขณะเดิน | G21: 0.5 | H21: CRITICAL | I21: Operator | J21: D | K21: D | L21: D | M21: D | N21: D | O21: D | P21: D | Q21: D | R21: D | S21: D | T21: D | U21: D | V21: D2, D5, D8
A22: H-14 | B22: ไฮดรอลิก | C22: H13 | D22: Relief valve: รั่วจากแต่ละส่วน | E22: I | F22: W * | G22: 0.5 | H22: HIGH | I22: Operator | J22: W | K22: W | L22: W | M22: W | N22: W | O22: W | P22: W | Q22: W | R22: W | S22: W | T22: W | U22: W | V22: W9
A23: H-15 | B23: ไฮดรอลิก | C23: H13 | D23: Relief valve: ทดสอบหมุน Handle | E23: I/A | F23: 6M * | G23: 5 | H23: HIGH | I23: ผู้ได้รับมอบหมาย * | O23: S | U23: S | V23: P7
A24: H-16 | B24: ไฮดรอลิก | C24: H14 | D24: เกจแรงดัน: ชี้ 0 หลังเลิกงาน | E24: I | F24: D · หลังเลิกงาน | G24: 0.5 | H24: HIGH | I24: Operator | J24: D | K24: D | L24: D | M24: D | N24: D | O24: D | P24: D | Q24: D | R24: D | S24: D | T24: D | U24: D | V24: D10
A25: H-17 | B25: ไฮดรอลิก | C25: H14 | D25: แถบสีเขียว/แดงบนเกจและเทอร์โมมิเตอร์ | E25: I | F25: W * | G25: 0.5 | H25: HIGH | I25: Operator | J25: W | K25: W | L25: W | M25: W | N25: W | O25: W | P25: W | Q25: W | R25: W | S25: W | T25: W | U25: W | V25: W13
A26: H-18 | B26: ไฮดรอลิก | C26: H15 | D26: Solenoid valve: เสียงคราง “บูน” | E26: I | F26: D · ขณะเดิน | G26: 0.5 | H26: CRITICAL | I26: Operator | J26: D | K26: D | L26: D | M26: D | N26: D | O26: D | P26: D | Q26: D | R26: D | S26: D | T26: D | U26: D | V26: D9
A27: H-19 | B27: ไฮดรอลิก | C27: H16 | D27: Solenoid valve: สลับทิศราบรื่น | E27: I | F27: D · ขณะเดิน | G27: 0.5 | H27: CRITICAL | I27: Operator | J27: D | K27: D | L27: D | M27: D | N27: D | O27: D | P27: D | Q27: D | R27: D | S27: D | T27: D | U27: D | V27: D7, D9
A28: H-20 | B28: ไฮดรอลิก | C28: H17 | D28: Solenoid valve: รั่ว · โบลต์ · สายไฟ | E28: C/I/T | F28: W * | G28: 2 | H28: CRITICAL | I28: Operator | J28: W | K28: W | L28: W | M28: W | N28: W | O28: W | P28: W | Q28: W | R28: W | S28: W | T28: W | U28: W | V28: W10, W11, W12
A29: H-21 | B29: ไฮดรอลิก | C29: H18 | D29: การเคลื่อนที่ + เวลาต่อรอบ | E29: I | F29: D · ขณะเดิน | G29: 1 | H29: HIGH | I29: Operator | J29: D | K29: D | L29: D | M29: D | N29: D | O29: D | P29: D | Q29: D | R29: D | S29: D | T29: D | U29: D | V29: D7
A30: ④ กระบอกสูบ (Actuator)
A31: H-22 | B31: ไฮดรอลิก | C31: H19 | D31: ก้านสูบ / ส่วนเลื่อน | E31: C | F31: D · หลังเลิกงาน | G31: 1 | H31: CRITICAL | I31: Operator | J31: D | K31: D | L31: D | M31: D | N31: D | O31: D | P31: D | Q31: D | R31: D | S31: D | T31: D | U31: D | V31: D14
A32: H-23 | B32: ไฮดรอลิก | C32: H20 | D32: ก้านสูบ · Dust seal · รอยรั่ว | E32: I | F32: W * | G32: 2 | H32: CRITICAL | I32: Operator | J32: W | K32: W | L32: W | M32: W | N32: W | O32: W | P32: W | Q32: W | R32: W | S32: W | T32: W | U32: W | V32: W1, W3, W4
A33: H-24 | B33: ไฮดรอลิก | C33: H21 | D33: โบลต์ / น็อต กระบอกสูบ | E33: T | F33: W * | G33: 1 | H33: CRITICAL | I33: Operator | J33: W | K33: W | L33: W | M33: W | N33: W | O33: W | P33: W | Q33: W | R33: W | S33: W | T33: W | U33: W | V33: W2
A34: H-25 | B34: ไฮดรอลิก | C34: H22 | D34: Cushion valve | E34: A | F34: เมื่อพบ * | G34: 5 | H34: HIGH | I34: ผู้ได้รับมอบหมาย * | V34: —
A35: ⑤ ท่อ · สาย · ซีล (Piping)
A36: H-26 | B36: ไฮดรอลิก | C36: H23 | D36: สายแรงดันสูง | E36: I | F36: W * | G36: 2 | H36: CRITICAL | I36: Operator | J36: W | K36: W | L36: W | M36: W | N36: W | O36: W | P36: W | Q36: W | R36: W | S36: W | T36: W | U36: W | V36: W5, W6, W8
A37: H-27 | B37: ไฮดรอลิก | C37: H25 | D37: ข้อต่อท่อ · O-ring: รอยรั่ว | E37: I/T | F37: W * | G37: 2 | H37: HIGH | I37: Operator | J37: W | K37: W | L37: W | M37: W | N37: W | O37: W | P37: W | Q37: W | R37: W | S37: W | T37: W | U37: W | V37: D12, D13
A38: H-28 | B38: ไฮดรอลิก | C38: H24 | D38: Lock clamp · Band | E38: T/I | F38: W * | G38: 1 | H38: CRITICAL | I38: Operator | J38: W | K38: W | L38: W | M38: W | N38: W | O38: W | P38: W | Q38: W | R38: W | S38: W | T38: W | U38: W | V38: W7
A39: ระบบลม
A40: ① ระบบท่อลม (Air piping)
A41: P-01 | B41: ระบบลม | C41: P02 | D41: ท่อลมสั่น · หน้าแปลน · โบลต์ · ที่ยึดท่อ | E41: I/T | F41: D · ขณะเดิน | G41: 1 | H41: HIGH | I41: Operator | J41: D | K41: D | L41: D | M41: D | N41: D | O41: D | P41: D | Q41: D | R41: D | S41: D | T41: D | U41: D | V41: D6, D10
...

Sheet Monthly_Load
A1: Monthly Load — เวลา AM ต่อเดือน (นาที)
A2: สูตรอ่านจาก AM_Calendar · ช่องเหลือง = วันทำงาน / จำนวนสัปดาห์ต่อเดือน (ค่าตัวอย่าง [ASSUME] แก้ตามปฏิทินโรงงาน) · ตามรอบ = ผลรวมเวลาของ Q/S/A ในเดือนนั้น
A4: รายการ | B4: ม.ค. | C4: ก.พ. | D4: มี.ค. | E4: เม.ย. | F4: พ.ค. | G4: มิ.ย. | H4: ก.ค. | I4: ส.ค. | J4: ก.ย. | K4: ต.ค. | L4: พ.ย. | M4: ธ.ค. | N4: รวมทั้งปี
A5: วันทำงานในเดือน (ตัวอย่าง [ASSUME]) | B5: 26 | C5: 26 | D5: 26 | E5: 26 | F5: 26 | G5: 26 | H5: 26 | I5: 26 | J5: 26 | K5: 26 | L5: 26 | M5: 26
A6: จำนวนสัปดาห์ในเดือน (ตัวอย่าง [ASSUME]) | B6: 4 | C6: 4 | D6: 4 | E6: 4 | F6: 4 | G6: 4 | H6: 4 | I6: 4 | J6: 4 | K6: 4 | L6: 4 | M6: 4
A8: ระบบไฮดรอลิก
A9: งานรายวัน (นาที/วัน × วันทำงาน) | B9: =SUMIFS(AM_Calendar!$G$7:$G$68,AM_Calendar!$B$7:$B$68,"ไฮดรอลิก",AM_Calendar!$F$7:$F$68,"D*")*B$5 -> 286 | C9: =SUMIFS(AM_Calendar!$G$7:$G$68,AM_Calendar!$B$7:$B$68,"ไฮดรอลิก",AM_Calendar!$F$7:$F$68,"D*")*C$5 -> 286 | D9: =SUMIFS(AM_Calendar!$G$7:$G$68,AM_Calendar!$B$7:$B$68,"ไฮดรอลิก",AM_Calendar!$F$7:$F$68,"D*")*D$5 -> 286 | E9: =SUMIFS(AM_Calendar!$G$7:$G$68,AM_Calendar!$B$7:$B$68,"ไฮดรอลิก",AM_Calendar!$F$7:$F$68,"D*")*E$5 -> 286 | F9: =SUMIFS(AM_Calendar!$G$7:$G$68,AM_Calendar!$B$7:$B$68,"ไฮดรอลิก",AM_Calendar!$F$7:$F$68,"D*")*F$5 -> 286 | G9: =SUMIFS(AM_Calendar!$G$7:$G$68,AM_Calendar!$B$7:$B$68,"ไฮดรอลิก",AM_Calendar!$F$7:$F$68,"D*")*G$5 -> 286 | H9: =SUMIFS(AM_Calendar!$G$7:$G$68,AM_Calendar!$B$7:$B$68,"ไฮดรอลิก",AM_Calendar!$F$7:$F$68,"D*")*H$5 -> 286 | I9: =SUMIFS(AM_Calendar!$G$7:$G$68,AM_Calendar!$B$7:$B$68,"ไฮดรอลิก",AM_Calendar!$F$7:$F$68,"D*")*I$5 -> 286 | ... M9: =SUMIFS(AM_Calendar!$G$7:$G$68,AM_Calendar!$B$7:$B$68,"ไฮดรอลิก",AM_Calendar!$F$7:$F$68,"D*")*M$5 -> 286 | N9: =SUM(B9:M9) -> 3432
A10: งานรายสัปดาห์ (นาที/สัปดาห์ × สัปดาห์) | B10: =SUMIFS(AM_Calendar!$G$7:$G$68,AM_Calendar!$B$7:$B$68,"ไฮดรอลิก",AM_Calendar!$F$7:$F$68,"W*")*B$6 -> 56 | C10: =SUMIFS(AM_Calendar!$G$7:$G$68,AM_Calendar!$B$7:$B$68,"ไฮดรอลิก",AM_Calendar!$F$7:$F$68,"W*")*C$6 -> 56 | D10: =SUMIFS(AM_Calendar!$G$7:$G$68,AM_Calendar!$B$7:$B$68,"ไฮดรอลิก",AM_Calendar!$F$7:$F$68,"W*")*D$6 -> 56 | E10: =SUMIFS(AM_Calendar!$G$7:$G$68,AM_Calendar!$B$7:$B$68,"ไฮดรอลิก",AM_Calendar!$F$7:$F$68,"W*")*E$6 -> 56 | F10: =SUMIFS(AM_Calendar!$G$7:$G$68,AM_Calendar!$B$7:$B$68,"ไฮดรอลิก",AM_Calendar!$F$7:$F$68,"W*")*F$6 -> 56 | G10: =SUMIFS(AM_Calendar!$G$7:$G$68,AM_Calendar!$B$7:$B$68,"ไฮดรอลิก",AM_Calendar!$F$7:$F$68,"W*")*G$6 -> 56 | H10: =SUMIFS(AM_Calendar!$G$7:$G$68,AM_Calendar!$B$7:$B$68,"ไฮดรอลิก",AM_Calendar!$F$7:$F$68,"W*")*H$6 -> 56 | I10: =SUMIFS(AM_Calendar!$G$7:$G$68,AM_Calendar!$B$7:$B$68,"ไฮดรอลิก",AM_Calendar!$F$7:$F$68,"W*")*I$6 -> 56 | ... M10: =SUMIFS(AM_Calendar!$G$7:$G$68,AM_Calendar!$B$7:$B$68,"ไฮดรอลิก",AM_Calendar!$F$7:$F$68,"W*")*M$6 -> 56 | N10: =SUM(B10:M10) -> 672
A11: งานตามรอบ Q / S / A | B11: =SUMIFS(AM_Calendar!$G$7:$G$68,AM_Calendar!$B$7:$B$68,"ไฮดรอลิก",AM_Calendar!$J$7:$J$68,"Q")+SUMIFS(AM_Calendar!$G$7:$G$68,AM_Calendar!$B$7:$B$68,"ไฮดรอลิก",AM_Calendar!$J$7:$J$68,"S")+SUMIFS(AM_Calendar!$G$7:$G$68,AM_Calendar!$B$7:$B$68,"ไฮดรอลิก",AM_Calendar!$J$7:$J$68,"A") -> 0 | C11: =SUMIFS(AM_Calendar!$G$7:$G$68,AM_Calendar!$B$7:$B$68,"ไฮดรอลิก",AM_Calendar!$K$7:$K$68,"Q")+SUMIFS(AM_Calendar!$G$7:$G$68,AM_Calendar!$B$7:$B$68,"ไฮดรอลิก",AM_Calendar!$K$7:$K$68,"S")+SUMIFS(AM_Calendar!$G$7:$G$68,AM_Calendar!$B$7:$B$68,"ไฮดรอลิก",AM_Calendar!$K$7:$K$68,"A") -> 0 | D11: =SUMIFS(AM_Calendar!$G$7:$G$68,AM_Calendar!$B$7:$B$68,"ไฮดรอลิก",AM_Calendar!$L$7:$L$68,"Q")+SUMIFS(AM_Calendar!$G$7:$G$68,AM_Calendar!$B$7:$B$68,"ไฮดรอลิก",AM_Calendar!$L$7:$L$68,"S")+SUMIFS(AM_Calendar!$G$7:$G$68,AM_Calendar!$B$7:$B$68,"ไฮดรอลิก",AM_Calendar!$L$7:$L$68,"A") -> 0 | E11: =SUMIFS(AM_Calendar!$G$7:$G$68,AM_Calendar!$B$7:$B$68,"ไฮดรอลิก",AM_Calendar!$M$7:$M$68,"Q")+SUMIFS(AM_Calendar!$G$7:$G$68,AM_Calendar!$B$7:$B$68,"ไฮดรอลิก",AM_Calendar!$M$7:$M$68,"S")+SUMIFS(AM_Calendar!$G$7:$G$68,AM_Calendar!$B$7:$B$68,"ไฮดรอลิก",AM_Calendar!$M$7:$M$68,"A") -> 0 | F11: =SUMIFS(AM_Calendar!$G$7:$G$68,AM_Calendar!$B$7:$B$68,"ไฮดรอลิก",AM_Calendar!$N$7:$N$68,"Q")+SUMIFS(AM_Calendar!$G$7:$G$68,AM_Calendar!$B$7:$B$68,"ไฮดรอลิก",AM_Calendar!$N$7:$N$68,"S")+SUMIFS(AM_Calendar!$G$7:$G$68,AM_Calendar!$B$7:$B$68,"ไฮดรอลิก",AM_Calendar!$N$7:$N$68,"A") -> 0 | G11: =SUMIFS(AM_Calendar!$G$7:$G$68,AM_Calendar!$B$7:$B$68,"ไฮดรอลิก",AM_Calendar!$O$7:$O$68,"Q")+SUMIFS(AM_Calendar!$G$7:$G$68,AM_Calendar!$B$7:$B$68,"ไฮดรอลิก",AM_Calendar!$O$7:$O$68,"S")+SUMIFS(AM_Calendar!$G$7:$G$68,AM_Calendar!$B$7:$B$68,"ไฮดรอลิก",AM_Calendar!$O$7:$O$68,"A") -> 7 | H11: =SUMIFS(AM_Calendar!$G$7:$G$68,AM_Calendar!$B$7:$B$68,"ไฮดรอลิก",AM_Calendar!$P$7:$P$68,"Q")+SUMIFS(AM_Calendar!$G$7:$G$68,AM_Calendar!$B$7:$B$68,"ไฮดรอลิก",AM_Calendar!$P$7:$P$68,"S")+SUMIFS(AM_Calendar!$G$7:$G$68,AM_Calendar!$B$7:$B$68,"ไฮดรอลิก",AM_Calendar!$P$7:$P$68,"A") -> 0 | I11: =SUMIFS(AM_Calendar!$G$7:$G$68,AM_Calendar!$B$7:$B$68,"ไฮดรอลิก",AM_Calendar!$Q$7:$Q$68,"Q")+SUMIFS(AM_Calendar!$G$7:$G$68,AM_Calendar!$B$7:$B$68,"ไฮดรอลิก",AM_Calendar!$Q$7:$Q$68,"S")+SUMIFS(AM_Calendar!$G$7:$G$68,AM_Calendar!$B$7:$B$68,"ไฮดรอลิก",AM_Calendar!$Q$7:$Q$68,"A") -> 0 | J11: =SUMIFS(AM_Calendar!$G$7:$G$68,AM_Calendar!$B$7:$B$68,"ไฮดรอลิก",AM_Calendar!$R$7:$R$68,"Q")+SUMIFS(AM_Calendar!$G$7:$G$68,AM_Calendar!$B$7:$B$68,"ไฮดรอลิก",AM_Calendar!$R$7:$R$68,"S")+SUMIFS(AM_Calendar!$G$7:$G$68,AM_Calendar!$B$7:$B$68,"ไฮดรอลิก",AM_Calendar!$R$7:$R$68,"A") -> 0 | K11: =SUMIFS(AM_Calendar!$G$7:$G$68,AM_Calendar!$B$7:$B$68,"ไฮดรอลิก",AM_Calendar!$S$7:$S$68,"Q")+SUMIFS(AM_Calendar!$G$7:$G$68,AM_Calendar!$B$7:$B$68,"ไฮดรอลิก",AM_Calendar!$S$7:$S$68,"S")+SUMIFS(AM_Calendar!$G$7:$G$68,AM_Calendar!$B$7:$B$68,"ไฮดรอลิก",AM_Calendar!$S$7:$S$68,"A") -> 0 | L11: =SUMIFS(AM_Calendar!$G$7:$G$68,AM_Calendar!$B$7:$B$68,"ไฮดรอลิก",AM_Calendar!$T$7:$T$68,"Q")+SUMIFS(AM_Calendar!$G$7:$G$68,AM_Calendar!$B$7:$B$68,"ไฮดรอลิก",AM_Calendar!$T$7:$T$68,"S")+SUMIFS(AM_Calendar!$G$7:$G$68,AM_Calendar!$B$7:$B$68,"ไฮดรอลิก",AM_Calendar!$T$7:$T$68,"A") -> 0 | M11: =SUMIFS(AM_Calendar!$G$7:$G$68,AM_Calendar!$B$7:$B$68,"ไฮดรอลิก",AM_Calendar!$U$7:$U$68,"Q")+SUMIFS(AM_Calendar!$G$7:$G$68,AM_Calendar!$B$7:$B$68,"ไฮดรอลิก",AM_Calendar!$U$7:$U$68,"S")+SUMIFS(AM_Calendar!$G$7:$G$68,AM_Calendar!$B$7:$B$68,"ไฮดรอลิก",AM_Calendar!$U$7:$U$68,"A") -> 27 | N11: =SUM(B11:M11) -> 34
A12: รวมไฮดรอลิก | B12: =SUM(B9:B11) -> 342 | C12: =SUM(C9:C11) -> 342 | D12: =SUM(D9:D11) -> 342 | E12: =SUM(E9:E11) -> 342 | F12: =SUM(F9:F11) -> 342 | G12: =SUM(G9:G11) -> 349 | H12: =SUM(H9:H11) -> 342 | I12: =SUM(I9:I11) -> 342 | ... M12: =SUM(M9:M11) -> 369 | N12: =SUM(B12:M12) -> 4138
A14: ระบบลม
A15: งานรายวัน (นาที/วัน × วันทำงาน) | B15: =SUMIFS(AM_Calendar!$G$7:$G$68,AM_Calendar!$B$7:$B$68,"ระบบลม",AM_Calendar!$F$7:$F$68,"D*")*B$5 -> 169 | C15: =SUMIFS(AM_Calendar!$G$7:$G$68,AM_Calendar!$B$7:$B$68,"ระบบลม",AM_Calendar!$F$7:$F$68,"D*")*C$5 -> 169 | D15: =SUMIFS(AM_Calendar!$G$7:$G$68,AM_Calendar!$B$7:$B$68,"ระบบลม",AM_Calendar!$F$7:$F$68,"D*")*D$5 -> 169 | E15: =SUMIFS(AM_Calendar!$G$7:$G$68,AM_Calendar!$B$7:$B$68,"ระบบลม",AM_Calendar!$F$7:$F$68,"D*")*E$5 -> 169 | F15: =SUMIFS(AM_Calendar!$G$7:$G$68,AM_Calendar!$B$7:$B$68,"ระบบลม",AM_Calendar!$F$7:$F$68,"D*")*F$5 -> 169 | G15: =SUMIFS(AM_Calendar!$G$7:$G$68,AM_Calendar!$B$7:$B$68,"ระบบลม",AM_Calendar!$F$7:$F$68,"D*")*G$5 -> 169 | H15: =SUMIFS(AM_Calendar!$G$7:$G$68,AM_Calendar!$B$7:$B$68,"ระบบลม",AM_Calendar!$F$7:$F$68,"D*")*H$5 -> 169 | I15: =SUMIFS(AM_Calendar!$G$7:$G$68,AM_Calendar!$B$7:$B$68,"ระบบลม",AM_Calendar!$F$7:$F$68,"D*")*I$5 -> 169 | ... M15: =SUMIFS(AM_Calendar!$G$7:$G$68,AM_Calendar!$B$7:$B$68,"ระบบลม",AM_Calendar!$F$7:$F$68,"D*")*M$5 -> 169 | N15: =SUM(B15:M15) -> 2028
A16: งานรายสัปดาห์ (นาที/สัปดาห์ × สัปดาห์) | B16: =SUMIFS(AM_Calendar!$G$7:$G$68,AM_Calendar!$B$7:$B$68,"ระบบลม",AM_Calendar!$F$7:$F$68,"W*")*B$6 -> 26 | C16: =SUMIFS(AM_Calendar!$G$7:$G$68,AM_Calendar!$B$7:$B$68,"ระบบลม",AM_Calendar!$F$7:$F$68,"W*")*C$6 -> 26 | D16: =SUMIFS(AM_Calendar!$G$7:$G$68,AM_Calendar!$B$7:$B$68,"ระบบลม",AM_Calendar!$F$7:$F$68,"W*")*D$6 -> 26 | E16: =SUMIFS(AM_Calendar!$G$7:$G$68,AM_Calendar!$B$7:$B$68,"ระบบลม",AM_Calendar!$F$7:$F$68,"W*")*E$6 -> 26 | F16: =SUMIFS(AM_Calendar!$G$7:$G$68,AM_Calendar!$B$7:$B$68,"ระบบลม",AM_Calendar!$F$7:$F$68,"W*")*F$6 -> 26 | G16: =SUMIFS(AM_Calendar!$G$7:$G$68,AM_Calendar!$B$7:$B$68,"ระบบลม",AM_Calendar!$F$7:$F$68,"W*")*G$6 -> 26 | H16: =SUMIFS(AM_Calendar!$G$7:$G$68,AM_Calendar!$B$7:$B$68,"ระบบลม",AM_Calendar!$F$7:$F$68,"W*")*H$6 -> 26 | I16: =SUMIFS(AM_Calendar!$G$7:$G$68,AM_Calendar!$B$7:$B$68,"ระบบลม",AM_Calendar!$F$7:$F$68,"W*")*I$6 -> 26 | ... M16: =SUMIFS(AM_Calendar!$G$7:$G$68,AM_Calendar!$B$7:$B$68,"ระบบลม",AM_Calendar!$F$7:$F$68,"W*")*M$6 -> 26 | N16: =SUM(B16:M16) -> 312
A17: งานตามรอบ Q / S / A | B17: =SUMIFS(AM_Calendar!$G$7:$G$68,AM_Calendar!$B$7:$B$68,"ระบบลม",AM_Calendar!$J$7:$J$68,"Q")+SUMIFS(AM_Calendar!$G$7:$G$68,AM_Calendar!$B$7:$B$68,"ระบบลม",AM_Calendar!$J$7:$J$68,"S")+SUMIFS(AM_Calendar!$G$7:$G$68,AM_Calendar!$B$7:$B$68,"ระบบลม",AM_Calendar!$J$7:$J$68,"A") -> 24 | C17: =SUMIFS(AM_Calendar!$G$7:$G$68,AM_Calendar!$B$7:$B$68,"ระบบลม",AM_Calendar!$K$7:$K$68,"Q")+SUMIFS(AM_Calendar!$G$7:$G$68,AM_Calendar!$B$7:$B$68,"ระบบลม",AM_Calendar!$K$7:$K$68,"S")+SUMIFS(AM_Calendar!$G$7:$G$68,AM_Calendar!$B$7:$B$68,"ระบบลม",AM_Calendar!$K$7:$K$68,"A") -> 0 | D17: =SUMIFS(AM_Calendar!$G$7:$G$68,AM_Calendar!$B$7:$B$68,"ระบบลม",AM_Calendar!$L$7:$L$68,"Q")+SUMIFS(AM_Calendar!$G$7:$G$68,AM_Calendar!$B$7:$B$68,"ระบบลม",AM_Calendar!$L$7:$L$68,"S")+SUMIFS(AM_Calendar!$G$7:$G$68,AM_Calendar!$B$7:$B$68,"ระบบลม",AM_Calendar!$L$7:$L$68,"A") -> 0 | E17: =SUMIFS(AM_Calendar!$G$7:$G$68,AM_Calendar!$B$7:$B$68,"ระบบลม",AM_Calendar!$M$7:$M$68,"Q")+SUMIFS(AM_Calendar!$G$7:$G$68,AM_Calendar!$B$7:$B$68,"ระบบลม",AM_Calendar!$M$7:$M$68,"S")+SUMIFS(AM_Calendar!$G$7:$G$68,AM_Calendar!$B$7:$B$68,"ระบบลม",AM_Calendar!$M$7:$M$68,"A") -> 24 | F17: =SUMIFS(AM_Calendar!$G$7:$G$68,AM_Calendar!$B$7:$B$68,"ระบบลม",AM_Calendar!$N$7:$N$68,"Q")+SUMIFS(AM_Calendar!$G$7:$G$68,AM_Calendar!$B$7:$B$68,"ระบบลม",AM_Calendar!$N$7:$N$68,"S")+SUMIFS(AM_Calendar!$G$7:$G$68,AM_Calendar!$B$7:$B$68,"ระบบลม",AM_Calendar!$N$7:$N$68,"A") -> 0 | G17: =SUMIFS(AM_Calendar!$G$7:$G$68,AM_Calendar!$B$7:$B$68,"ระบบลม",AM_Calendar!$O$7:$O$68,"Q")+SUMIFS(AM_Calendar!$G$7:$G$68,AM_Calendar!$B$7:$B$68,"ระบบลม",AM_Calendar!$O$7:$O$68,"S")+SUMIFS(AM_Calendar!$G$7:$G$68,AM_Calendar!$B$7:$B$68,"ระบบลม",AM_Calendar!$O$7:$O$68,"A") -> 0 | H17: =SUMIFS(AM_Calendar!$G$7:$G$68,AM_Calendar!$B$7:$B$68,"ระบบลม",AM_Calendar!$P$7:$P$68,"Q")+SUMIFS(AM_Calendar!$G$7:$G$68,AM_Calendar!$B$7:$B$68,"ระบบลม",AM_Calendar!$P$7:$P$68,"S")+SUMIFS(AM_Calendar!$G$7:$G$68,AM_Calendar!$B$7:$B$68,"ระบบลม",AM_Calendar!$P$7:$P$68,"A") -> 134 | I17: =SUMIFS(AM_Calendar!$G$7:$G$68,AM_Calendar!$B$7:$B$68,"ระบบลม",AM_Calendar!$Q$7:$Q$68,"Q")+SUMIFS(AM_Calendar!$G$7:$G$68,AM_Calendar!$B$7:$B$68,"ระบบลม",AM_Calendar!$Q$7:$Q$68,"S")+SUMIFS(AM_Calendar!$G$7:$G$68,AM_Calendar!$B$7:$B$68,"ระบบลม",AM_Calendar!$Q$7:$Q$68,"A") -> 0 | J17: =SUMIFS(AM_Calendar!$G$7:$G$68,AM_Calendar!$B$7:$B$68,"ระบบลม",AM_Calendar!$R$7:$R$68,"Q")+SUMIFS(AM_Calendar!$G$7:$G$68,AM_Calendar!$B$7:$B$68,"ระบบลม",AM_Calendar!$R$7:$R$68,"S")+SUMIFS(AM_Calendar!$G$7:$G$68,AM_Calendar!$B$7:$B$68,"ระบบลม",AM_Calendar!$R$7:$R$68,"A") -> 0 | K17: =SUMIFS(AM_Calendar!$G$7:$G$68,AM_Calendar!$B$7:$B$68,"ระบบลม",AM_Calendar!$S$7:$S$68,"Q")+SUMIFS(AM_Calendar!$G$7:$G$68,AM_Calendar!$B$7:$B$68,"ระบบลม",AM_Calendar!$S$7:$S$68,"S")+SUMIFS(AM_Calendar!$G$7:$G$68,AM_Calendar!$B$7:$B$68,"ระบบลม",AM_Calendar!$S$7:$S$68,"A") -> 24 | L17: =SUMIFS(AM_Calendar!$G$7:$G$68,AM_Calendar!$B$7:$B$68,"ระบบลม",AM_Calendar!$T$7:$T$68,"Q")+SUMIFS(AM_Calendar!$G$7:$G$68,AM_Calendar!$B$7:$B$68,"ระบบลม",AM_Calendar!$T$7:$T$68,"S")+SUMIFS(AM_Calendar!$G$7:$G$68,AM_Calendar!$B$7:$B$68,"ระบบลม",AM_Calendar!$T$7:$T$68,"A") -> 0 | M17: =SUMIFS(AM_Calendar!$G$7:$G$68,AM_Calendar!$B$7:$B$68,"ระบบลม",AM_Calendar!$U$7:$U$68,"Q")+SUMIFS(AM_Calendar!$G$7:$G$68,AM_Calendar!$B$7:$B$68,"ระบบลม",AM_Calendar!$U$7:$U$68,"S")+SUMIFS(AM_Calendar!$G$7:$G$68,AM_Calendar!$B$7:$B$68,"ระบบลม",AM_Calendar!$U$7:$U$68,"A") -> 0 | N17: =SUM(B17:M17) -> 206
A18: รวมระบบลม | B18: =SUM(B15:B17) -> 219 | C18: =SUM(C15:C17) -> 195 | D18: =SUM(D15:D17) -> 195 | E18: =SUM(E15:E17) -> 219 | F18: =SUM(F15:F17) -> 195 | G18: =SUM(G15:G17) -> 195 | H18: =SUM(H15:H17) -> 329 | I18: =SUM(I15:I17) -> 195 | ... M18: =SUM(M15:M17) -> 195 | N18: =SUM(B18:M18) -> 2546
A20: รวมทั้งสองระบบ (นาที/เดือน) | B20: =B12+B18 -> 561 | C20: =C12+C18 -> 537 | D20: =D12+D18 -> 537 | E20: =E12+E18 -> 561 | F20: =F12+F18 -> 537 | G20: =G12+G18 -> 544 | H20: =H12+H18 -> 671 | I20: =I12+I18 -> 537 | ... M20: =M12+M18 -> 564 | N20: =SUM(B20:M20) -> 6684
A21: ในนั้นเป็นงาน PM ตามรอบ (ผู้รับผิดชอบ PM) | B21: =SUMIFS(AM_Calendar!$G$7:$G$68,AM_Calendar!$B$7:$B$68,"ไฮดรอลิก",AM_Calendar!$J$7:$J$68,"Q",AM_Calendar!$I$7:$I$68,"PM*")+SUMIFS(AM_Calendar!$G$7:$G$68,AM_Calendar!$B$7:$B$68,"ไฮดรอลิก",AM_Calendar!$J$7:$J$68,"S",AM_Calendar!$I$7:$I$68,"PM*")+SUMIFS(AM_Calendar!$G$7:$G$68,AM_Calendar!$B$7:$B$68,"ไฮดรอลิก",AM_Calendar!$J$7:$J$68,"A",AM_Calendar!$I$7:$I$68,"PM*")+SUMIFS(AM_Calendar!$G$7:$G$68,AM_Calendar!$B$7:$B$68,"ระบบลม",AM_Calendar!$J$7:$J$68,"Q",AM_Calendar!$I$7:$I$68,"PM*")+SUMIFS(AM_Calendar!$G$7:$G$68,AM_Calendar!$B$7:$B$68,"ระบบลม",AM_Calendar!$J$7:$J$68,"S",AM_Calendar!$I$7:$I$68,"PM*")+SUMIFS(AM_Calendar!$G$7:$G$68,AM_Calendar!$B$7:$B$68,"ระบบลม",AM_Calendar!$J$7:$J$68,"A",AM_Calendar!$I$7:$I$68,"PM*") -> 0 | C21: =SUMIFS(AM_Calendar!$G$7:$G$68,AM_Calendar!$B$7:$B$68,"ไฮดรอลิก",AM_Calendar!$K$7:$K$68,"Q",AM_Calendar!$I$7:$I$68,"PM*")+SUMIFS(AM_Calendar!$G$7:$G$68,AM_Calendar!$B$7:$B$68,"ไฮดรอลิก",AM_Calendar!$K$7:$K$68,"S",AM_Calendar!$I$7:$I$68,"PM*")+SUMIFS(AM_Calendar!$G$7:$G$68,AM_Calendar!$B$7:$B$68,"ไฮดรอลิก",AM_Calendar!$K$7:$K$68,"A",AM_Calendar!$I$7:$I$68,"PM*")+SUMIFS(AM_Calendar!$G$7:$G$68,AM_Calendar!$B$7:$B$68,"ระบบลม",AM_Calendar!$K$7:$K$68,"Q",AM_Calendar!$I$7:$I$68,"PM*")+SUMIFS(AM_Calendar!$G$7:$G$68,AM_Calendar!$B$7:$B$68,"ระบบลม",AM_Calendar!$K$7:$K$68,"S",AM_Calendar!$I$7:$I$68,"PM*")+SUMIFS(AM_Calendar!$G$7:$G$68,AM_Calendar!$B$7:$B$68,"ระบบลม",AM_Calendar!$K$7:$K$68,"A",AM_Calendar!$I$7:$I$68,"PM*") -> 0 | D21: =SUMIFS(AM_Calendar!$G$7:$G$68,AM_Calendar!$B$7:$B$68,"ไฮดรอลิก",AM_Calendar!$L$7:$L$68,"Q",AM_Calendar!$I$7:$I$68,"PM*")+SUMIFS(AM_Calendar!$G$7:$G$68,AM_Calendar!$B$7:$B$68,"ไฮดรอลิก",AM_Calendar!$L$7:$L$68,"S",AM_Calendar!$I$7:$I$68,"PM*")+SUMIFS(AM_Calendar!$G$7:$G$68,AM_Calendar!$B$7:$B$68,"ไฮดรอลิก",AM_Calendar!$L$7:$L$68,"A",AM_Calendar!$I$7:$I$68,"PM*")+SUMIFS(AM_Calendar!$G$7:$G$68,AM_Calendar!$B$7:$B$68,"ระบบลม",AM_Calendar!$L$7:$L$68,"Q",AM_Calendar!$I$7:$I$68,"PM*")+SUMIFS(AM_Calendar!$G$7:$G$68,AM_Calendar!$B$7:$B$68,"ระบบลม",AM_Calendar!$L$7:$L$68,"S",AM_Calendar!$I$7:$I$68,"PM*")+SUMIFS(AM_Calendar!$G$7:$G$68,AM_Calendar!$B$7:$B$68,"ระบบลม",AM_Calendar!$L$7:$L$68,"A",AM_Calendar!$I$7:$I$68,"PM*") -> 0 | E21: =SUMIFS(AM_Calendar!$G$7:$G$68,AM_Calendar!$B$7:$B$68,"ไฮดรอลิก",AM_Calendar!$M$7:$M$68,"Q",AM_Calendar!$I$7:$I$68,"PM*")+SUMIFS(AM_Calendar!$G$7:$G$68,AM_Calendar!$B$7:$B$68,"ไฮดรอลิก",AM_Calendar!$M$7:$M$68,"S",AM_Calendar!$I$7:$I$68,"PM*")+SUMIFS(AM_Calendar!$G$7:$G$68,AM_Calendar!$B$7:$B$68,"ไฮดรอลิก",AM_Calendar!$M$7:$M$68,"A",AM_Calendar!$I$7:$I$68,"PM*")+SUMIFS(AM_Calendar!$G$7:$G$68,AM_Calendar!$B$7:$B$68,"ระบบลม",AM_Calendar!$M$7:$M$68,"Q",AM_Calendar!$I$7:$I$68,"PM*")+SUMIFS(AM_Calendar!$G$7:$G$68,AM_Calendar!$B$7:$B$68,"ระบบลม",AM_Calendar!$M$7:$M$68,"S",AM_Calendar!$I$7:$I$68,"PM*")+SUMIFS(AM_Calendar!$G$7:$G$68,AM_Calendar!$B$7:$B$68,"ระบบลม",AM_Calendar!$M$7:$M$68,"A",AM_Calendar!$I$7:$I$68,"PM*") -> 0 | F21: =SUMIFS(AM_Calendar!$G$7:$G$68,AM_Calendar!$B$7:$B$68,"ไฮดรอลิก",AM_Calendar!$N$7:$N$68,"Q",AM_Calendar!$I$7:$I$68,"PM*")+SUMIFS(AM_Calendar!$G$7:$G$68,AM_Calendar!$B$7:$B$68,"ไฮดรอลิก",AM_Calendar!$N$7:$N$68,"S",AM_Calendar!$I$7:$I$68,"PM*")+SUMIFS(AM_Calendar!$G$7:$G$68,AM_Calendar!$B$7:$B$68,"ไฮดรอลิก",AM_Calendar!$N$7:$N$68,"A",AM_Calendar!$I$7:$I$68,"PM*")+SUMIFS(AM_Calendar!$G$7:$G$68,AM_Calendar!$B$7:$B$68,"ระบบลม",AM_Calendar!$N$7:$N$68,"Q",AM_Calendar!$I$7:$I$68,"PM*")+SUMIFS(AM_Calendar!$G$7:$G$68,AM_Calendar!$B$7:$B$68,"ระบบลม",AM_Calendar!$N$7:$N$68,"S",AM_Calendar!$I$7:$I$68,"PM*")+SUMIFS(AM_Calendar!$G$7:$G$68,AM_Calendar!$B$7:$B$68,"ระบบลม",AM_Calendar!$N$7:$N$68,"A",AM_Calendar!$I$7:$I$68,"PM*") -> 0 | G21: =SUMIFS(AM_Calendar!$G$7:$G$68,AM_Calendar!$B$7:$B$68,"ไฮดรอลิก",AM_Calendar!$O$7:$O$68,"Q",AM_Calendar!$I$7:$I$68,"PM*")+SUMIFS(AM_Calendar!$G$7:$G$68,AM_Calendar!$B$7:$B$68,"ไฮดรอลิก",AM_Calendar!$O$7:$O$68,"S",AM_Calendar!$I$7:$I$68,"PM*")+SUMIFS(AM_Calendar!$G$7:$G$68,AM_Calendar!$B$7:$B$68,"ไฮดรอลิก",AM_Calendar!$O$7:$O$68,"A",AM_Calendar!$I$7:$I$68,"PM*")+SUMIFS(AM_Calendar!$G$7:$G$68,AM_Calendar!$B$7:$B$68,"ระบบลม",AM_Calendar!$O$7:$O$68,"Q",AM_Calendar!$I$7:$I$68,"PM*")+SUMIFS(AM_Calendar!$G$7:$G$68,AM_Calendar!$B$7:$B$68,"ระบบลม",AM_Calendar!$O$7:$O$68,"S",AM_Calendar!$I$7:$I$68,"PM*")+SUMIFS(AM_Calendar!$G$7:$G$68,AM_Calendar!$B$7:$B$68,"ระบบลม",AM_Calendar!$O$7:$O$68,"A",AM_Calendar!$I$7:$I$68,"PM*") -> 0 | H21: =SUMIFS(AM_Calendar!$G$7:$G$68,AM_Calendar!$B$7:$B$68,"ไฮดรอลิก",AM_Calendar!$P$7:$P$68,"Q",AM_Calendar!$I$7:$I$68,"PM*")+SUMIFS(AM_Calendar!$G$7:$G$68,AM_Calendar!$B$7:$B$68,"ไฮดรอลิก",AM_Calendar!$P$7:$P$68,"S",AM_Calendar!$I$7:$I$68,"PM*")+SUMIFS(AM_Calendar!$G$7:$G$68,AM_Calendar!$B$7:$B$68,"ไฮดรอลิก",AM_Calendar!$P$7:$P$68,"A",AM_Calendar!$I$7:$I$68,"PM*")+SUMIFS(AM_Calendar!$G$7:$G$68,AM_Calendar!$B$7:$B$68,"ระบบลม",AM_Calendar!$P$7:$P$68,"Q",AM_Calendar!$I$7:$I$68,"PM*")+SUMIFS(AM_Calendar!$G$7:$G$68,AM_Calendar!$B$7:$B$68,"ระบบลม",AM_Calendar!$P$7:$P$68,"S",AM_Calendar!$I$7:$I$68,"PM*")+SUMIFS(AM_Calendar!$G$7:$G$68,AM_Calendar!$B$7:$B$68,"ระบบลม",AM_Calendar!$P$7:$P$68,"A",AM_Calendar!$I$7:$I$68,"PM*") -> 110 | I21: =SUMIFS(AM_Calendar!$G$7:$G$68,AM_Calendar!$B$7:$B$68,"ไฮดรอลิก",AM_Calendar!$Q$7:$Q$68,"Q",AM_Calendar!$I$7:$I$68,"PM*")+SUMIFS(AM_Calendar!$G$7:$G$68,AM_Calendar!$B$7:$B$68,"ไฮดรอลิก",AM_Calendar!$Q$7:$Q$68,"S",AM_Calendar!$I$7:$I$68,"PM*")+SUMIFS(AM_Calendar!$G$7:$G$68,AM_Calendar!$B$7:$B$68,"ไฮดรอลิก",AM_Calendar!$Q$7:$Q$68,"A",AM_Calendar!$I$7:$I$68,"PM*")+SUMIFS(AM_Calendar!$G$7:$G$68,AM_Calendar!$B$7:$B$68,"ระบบลม",AM_Calendar!$Q$7:$Q$68,"Q",AM_Calendar!$I$7:$I$68,"PM*")+SUMIFS(AM_Calendar!$G$7:$G$68,AM_Calendar!$B$7:$B$68,"ระบบลม",AM_Calendar!$Q$7:$Q$68,"S",AM_Calendar!$I$7:$I$68,"PM*")+SUMIFS(AM_Calendar!$G$7:$G$68,AM_Calendar!$B$7:$B$68,"ระบบลม",AM_Calendar!$Q$7:$Q$68,"A",AM_Calendar!$I$7:$I$68,"PM*") -> 0 | J21: =SUMIFS(AM_Calendar!$G$7:$G$68,AM_Calendar!$B$7:$B$68,"ไฮดรอลิก",AM_Calendar!$R$7:$R$68,"Q",AM_Calendar!$I$7:$I$68,"PM*")+SUMIFS(AM_Calendar!$G$7:$G$68,AM_Calendar!$B$7:$B$68,"ไฮดรอลิก",AM_Calendar!$R$7:$R$68,"S",AM_Calendar!$I$7:$I$68,"PM*")+SUMIFS(AM_Calendar!$G$7:$G$68,AM_Calendar!$B$7:$B$68,"ไฮดรอลิก",AM_Calendar!$R$7:$R$68,"A",AM_Calendar!$I$7:$I$68,"PM*")+SUMIFS(AM_Calendar!$G$7:$G$68,AM_Calendar!$B$7:$B$68,"ระบบลม",AM_Calendar!$R$7:$R$68,"Q",AM_Calendar!$I$7:$I$68,"PM*")+SUMIFS(AM_Calendar!$G$7:$G$68,AM_Calendar!$B$7:$B$68,"ระบบลม",AM_Calendar!$R$7:$R$68,"S",AM_Calendar!$I$7:$I$68,"PM*")+SUMIFS(AM_Calendar!$G$7:$G$68,AM_Calendar!$B$7:$B$68,"ระบบลม",AM_Calendar!$R$7:$R$68,"A",AM_Calendar!$I$7:$I$68,"PM*") -> 0 | K21: =SUMIFS(AM_Calendar!$G$7:$G$68,AM_Calendar!$B$7:$B$68,"ไฮดรอลิก",AM_Calendar!$S$7:$S$68,"Q",AM_Calendar!$I$7:$I$68,"PM*")+SUMIFS(AM_Calendar!$G$7:$G$68,AM_Calendar!$B$7:$B$68,"ไฮดรอลิก",AM_Calendar!$S$7:$S$68,"S",AM_Calendar!$I$7:$I$68,"PM*")+SUMIFS(AM_Calendar!$G$7:$G$68,AM_Calendar!$B$7:$B$68,"ไฮดรอลิก",AM_Calendar!$S$7:$S$68,"A",AM_Calendar!$I$7:$I$68,"PM*")+SUMIFS(AM_Calendar!$G$7:$G$68,AM_Calendar!$B$7:$B$68,"ระบบลม",AM_Calendar!$S$7:$S$68,"Q",AM_Calendar!$I$7:$I$68,"PM*")+SUMIFS(AM_Calendar!$G$7:$G$68,AM_Calendar!$B$7:$B$68,"ระบบลม",AM_Calendar!$S$7:$S$68,"S",AM_Calendar!$I$7:$I$68,"PM*")+SUMIFS(AM_Calendar!$G$7:$G$68,AM_Calendar!$B$7:$B$68,"ระบบลม",AM_Calendar!$S$7:$S$68,"A",AM_Calendar!$I$7:$I$68,"PM*") -> 0 | L21: =SUMIFS(AM_Calendar!$G$7:$G$68,AM_Calendar!$B$7:$B$68,"ไฮดรอลิก",AM_Calendar!$T$7:$T$68,"Q",AM_Calendar!$I$7:$I$68,"PM*")+SUMIFS(AM_Calendar!$G$7:$G$68,AM_Calendar!$B$7:$B$68,"ไฮดรอลิก",AM_Calendar!$T$7:$T$68,"S",AM_Calendar!$I$7:$I$68,"PM*")+SUMIFS(AM_Calendar!$G$7:$G$68,AM_Calendar!$B$7:$B$68,"ไฮดรอลิก",AM_Calendar!$T$7:$T$68,"A",AM_Calendar!$I$7:$I$68,"PM*")+SUMIFS(AM_Calendar!$G$7:$G$68,AM_Calendar!$B$7:$B$68,"ระบบลม",AM_Calendar!$T$7:$T$68,"Q",AM_Calendar!$I$7:$I$68,"PM*")+SUMIFS(AM_Calendar!$G$7:$G$68,AM_Calendar!$B$7:$B$68,"ระบบลม",AM_Calendar!$T$7:$T$68,"S",AM_Calendar!$I$7:$I$68,"PM*")+SUMIFS(AM_Calendar!$G$7:$G$68,AM_Calendar!$B$7:$B$68,"ระบบลม",AM_Calendar!$T$7:$T$68,"A",AM_Calendar!$I$7:$I$68,"PM*") -> 0 | M21: =SUMIFS(AM_Calendar!$G$7:$G$68,AM_Calendar!$B$7:$B$68,"ไฮดรอลิก",AM_Calendar!$U$7:$U$68,"Q",AM_Calendar!$I$7:$I$68,"PM*")+SUMIFS(AM_Calendar!$G$7:$G$68,AM_Calendar!$B$7:$B$68,"ไฮดรอลิก",AM_Calendar!$U$7:$U$68,"S",AM_Calendar!$I$7:$I$68,"PM*")+SUMIFS(AM_Calendar!$G$7:$G$68,AM_Calendar!$B$7:$B$68,"ไฮดรอลิก",AM_Calendar!$U$7:$U$68,"A",AM_Calendar!$I$7:$I$68,"PM*")+SUMIFS(AM_Calendar!$G$7:$G$68,AM_Calendar!$B$7:$B$68,"ระบบลม",AM_Calendar!$U$7:$U$68,"Q",AM_Calendar!$I$7:$I$68,"PM*")+SUMIFS(AM_Calendar!$G$7:$G$68,AM_Calendar!$B$7:$B$68,"ระบบลม",AM_Calendar!$U$7:$U$68,"S",AM_Calendar!$I$7:$I$68,"PM*")+SUMIFS(AM_Calendar!$G$7:$G$68,AM_Calendar!$B$7:$B$68,"ระบบลม",AM_Calendar!$U$7:$U$68,"A",AM_Calendar!$I$7:$I$68,"PM*") -> 20 | N21: =SUM(B21:M21) -> 130
A23: เดือนที่ภาระรวมสูงสุด | B23: =INDEX($B$4:$M$4,MATCH(MAX(B20:M20),B20:M20,0))&" · "&MAX(B20:M20)&" นาที" -> ก.ค. · 671 นาที
A25: เวลา AM รายวัน เทียบเป้า AM Step 3 (< 10 นาที/กะ) — กรณีเครื่องเดียวมีทั้ง 2 ระบบ
A26: ไฮดรอลิก (นาที/วัน) | B26: =SUMIFS(AM_Calendar!$G$7:$G$68,AM_Calendar!$B$7:$B$68,"ไฮดรอลิก",AM_Calendar!$F$7:$F$68,"D*") -> 11 | C26: =IF(B26<10,"ผ่าน","เกิน") -> เกิน
A27: ระบบลม (นาที/วัน) | B27: =SUMIFS(AM_Calendar!$G$7:$G$68,AM_Calendar!$B$7:$B$68,"ระบบลม",AM_Calendar!$F$7:$F$68,"D*") -> 6.5 | C27: =IF(B27<10,"ผ่าน","เกิน") -> ผ่าน
A28: รวม 2 ระบบ (นาที/วัน) | B28: =B26+B27 -> 17.5 | C28: =IF(B28<10,"ผ่าน","เกิน") -> เกิน
A29: เกินเป้า → ใช้ Kaizen ในชีท Kaizen_IoT_CBM ของ AM Standard (เช่น Match mark · แผ่นซับใต้จุดรั่ว · Auto drain) และจับเวลาจริงก่อนสรุป

Sheet Periodic_Record
A1: Periodic Record — แผน vs ผลจริง งานตามรอบ (3M / 6M / 1Y)
A2: เดือนตามแผนมาจาก AM_Calendar ตอนสร้างไฟล์ (ถ้าเลื่อนเดือนในปฏิทิน ให้แก้ช่องเดือนที่นี่ด้วย) · ผล: ○ ปกติ · △ เฝ้าดู · × ผิดปกติ (ติด F-tag)
A4: No. | B4: ระบบ | C4: กิจกรรม | D4: ความถี่ | E4: เดือนตามแผน | F4: เวลา (นาที) | G4: ผู้รับผิดชอบ | H4: วันที่ทำจริง | I4: ผู้ทำ | J4: ผล | K4: หมายเหตุ
A5: H-07 | B5: ไฮดรอลิก | C5: Filter: Vacuum meter / Indicator | D5: 6M | E5: มิ.ย. | F5: 2 | G5: Operator / PM *
A6: H-07 | B6: ไฮดรอลิก | C6: Filter: Vacuum meter / Indicator | D6: 6M | E6: ธ.ค. | F6: 2 | G6: Operator / PM *
A7: H-11 | B7: ไฮดรอลิก | C7: Coupling: ตั้งศูนย์ + จาระบี | D7: 1Y * | E7: ธ.ค. | F7: 20 | G7: PM
A8: H-15 | B8: ไฮดรอลิก | C8: Relief valve: ทดสอบหมุน Handle | D8: 6M * | E8: มิ.ย. | F8: 5 | G8: ผู้ได้รับมอบหมาย *
A9: H-15 | B9: ไฮดรอลิก | C9: Relief valve: ทดสอบหมุน Handle | D9: 6M * | E9: ธ.ค. | F9: 5 | G9: ผู้ได้รับมอบหมาย *
A10: P-02 | B10: ระบบลม | C10: ลมรั่ว: ระบบท่อ (Table 2) | D10: 3M | E10: ม.ค. | F10: 10 | G10: Operator / PM *
A11: P-02 | B11: ระบบลม | C11: ลมรั่ว: ระบบท่อ (Table 2) | D11: 3M | E11: เม.ย. | F11: 10 | G11: Operator / PM *
A12: P-02 | B12: ระบบลม | C12: ลมรั่ว: ระบบท่อ (Table 2) | D12: 3M | E12: ก.ค. | F12: 10 | G12: Operator / PM *
A13: P-02 | B13: ระบบลม | C13: ลมรั่ว: ระบบท่อ (Table 2) | D13: 3M | E13: ต.ค. | F13: 10 | G13: Operator / PM *
A14: P-12 | B14: ระบบลม | C14: Auto drain: ทำงาน | D14: 3M | E14: ม.ค. | F14: 1 | G14: Operator
A15: P-12 | B15: ระบบลม | C15: Auto drain: ทำงาน | D15: 3M | E15: เม.ย. | F15: 1 | G15: Operator
A16: P-12 | B16: ระบบลม | C16: Auto drain: ทำงาน | D16: 3M | E16: ก.ค. | F16: 1 | G16: Operator
... A41: P-22 | B41: ระบบลม | C41: ถอดตรวจกระบอกสูบ: Tube · O-ring · Packing | D41: 1Y | E41: ก.ค. | F41: 30 | G41: PM *
C43: ทำตามแผนแล้ว (%) | E43: =IFERROR(COUNTA(H5:H41)/ROWS(H5:H41),0) -> 0
C44: พบผิดปกติ (×) | E44: =COUNTIF(J5:J41,"×") -> 0
A46: งานตามเหตุการณ์ (ไม่มีเดือน) — บันทึกเมื่อเกิด
A47: H-12 | B47: ไฮดรอลิก | C47: โบลต์ฝาปั๊ม (หลังงานซ่อม) | D47: ทุกครั้งที่ซ่อม * | E47: — | F47: 5 | G47: PM
A48: H-25 | B48: ไฮดรอลิก | C48: Cushion valve | D48: เมื่อพบ * | E48: — | F48: 5 | G48: ผู้ได้รับมอบหมาย *

Sheet To_Confirm
A1: To Confirm — ประเด็นที่ต้องยืนยันก่อนใช้จริง
A2: ให้หัวหน้างาน / ฝ่ายซ่อมบำรุง / ฝ่ายวางแผนผลิต ยืนยัน
A4: No. | B4: ประเด็น | C4: รายละเอียด | D4: ที่มา / สถานะ | E4: ผู้ยืนยัน | F4: วันที่ | G4: ผล / ค่าที่ใช้
A5: 1 | B5: เดือนของงาน Q / S / A | C5: เกลี่ยแล้วไม่ให้ 1Y ของ 2 ระบบชนกัน · ต้องวางตรงแผนหยุดเครื่อง/วันหยุดยาว | D5: ข้อเสนอ *
A6: 2 | B6: วันทำงานและจำนวนสัปดาห์ต่อเดือน | C6: ค่าตัวอย่าง 26 วัน / 4 สัปดาห์ | D6: [ASSUME] → ปฏิทินโรงงาน
A7: 3 | B7: เวลาต่อกิจกรรม | C7: ประมาณการจาก AM Standard · จับเวลาจริงช่วงทดลองใช้ | D7: [INFER]
A8: 4 | B8: งานรายวันทำกะไหน | C8: เวลา AM รายวันคิดครั้งเดียวต่อวัน · ถ้าแบ่งหลายกะ ให้กำหนดกะที่รับผิดชอบ | D8: [DATA REQUIRED]
A9: 5 | B9: แบ่งงาน Operator (AM) / PM | C9: ผู้รับผิดชอบที่มี * เป็นข้อเสนอ (เช่น ถอดตรวจ 1 ปี = PM) | D9: ข้อเสนอ · AM Step 5 แบ่งบทบาท
A10: 6 | B10: Risk ในปฏิทิน | C10: สำเนาจาก FMEA ณ วันที่สร้าง · แก้ S/O/D แล้วต้องสร้างไฟล์ใหม่ | D10: จาก AM Standard
